Workbook
Name 分类定义区: CombineBQ!$A$3:$AI$68

Sheet CombineBQ
F1: EXPORT | M1: COST | R1: AI | AE1: SUBCONTRACTOR
G2: 1.23 | H2: 1.23 | I2: 1.23 | X2: =IF(E2>0,TRIM(_xlfn.REGEXREPLACE(_xlfn.REGEXREPLACE(C2,"^\s*(?:\d+\.\d+(?:\.\d+)*|-)\s+", ""),"[。.]+$", "")), "") | AE2: 1.05 | AG2: 0.07
A3: Main Key | B3: No. | C3: Description | D3: Unit | E3: Qty | F3: Factor | G3: Labor | H3: Material | I3: Equipment | J3: Rate | K3: Amount | M3: Labor | N3: Material | O3: Equipment | P3: Rate | Q3: Amount | R3: Discipline | S3: SortKey | T3: Category | U3: Subcategory | V3: Element | W3: BQ KEY | X3: CleanDescription | Y3: Norm Rate | Z3: Norm Amount | AA3: Ref Rate | AB3: Ref Amount | AE3: Labor | AF3: Material | AG3: Equipment | AH3: Rate | AI3: Amount
A4: {=_xlfn.LET( _xlpm.Item,C4, _xlpm.Unit,D4, _xlpm.DataRng,$C$4:C4, _xlpm.Level1,IFERROR(LOOKUP(2,1/ISNUMBER(FIND("【",_xlpm.DataRng)),_xlpm.DataRng),""), _xlpm.Level2,IFERROR(LOOKUP(2,1/ISNUMBER(FIND("《",_xlpm.DataRng)),_xlpm.DataRng),""), _xlpm.Level3,IFERROR(LOOKUP(2,1/ISNUMBER(FIND("{",_xlpm.DataRng)),_xlpm.DataRng),""), _xlpm.Strip,_xlfn.LAMBDA(_xlpm.x,MID(_xlfn.REGEXREPLACE(TRIM(_xlpm.x),"[~*_|]",""),2,9)), _xlpm.Hash,_xlfn.LAMBDA(_xlpm.x,IF(LEN(_xlpm.x)=0,0,SUMPRODUCT(CODE(MID(_xlpm.x,_xlfn.SEQUENCE(LEN(_xlpm.x)),1))*_xlfn.SEQUENCE(LEN(_xlpm.x))))), _xlpm.Strip(_xlpm.Level1)&"|"&_xlpm.Strip(_xlpm.Level2)&"|"&_xlpm.Strip(_xlpm.Level3)&"|"&_xlpm.Hash(_xlpm.Item&"@"&_xlpm.Unit&E4) )} | W4: {=_xlfn.LET( _xlpm.Item,S4, _xlpm.Unit,X4, _xlpm.Hash,_xlfn.LAMBDA(_xlpm.x,IF(LEN(_xlpm.x)=0,0,SUMPRODUCT(CODE(MID(_xlpm.x,_xlfn.SEQUENCE(LEN(_xlpm.x)),1))*_xlfn.SEQUENCE(LEN(_xlpm.x))))), _xlpm.Item&"|"&_xlpm.Hash(_xlpm.Unit) )}
C5: 【示例分部】 | K5: =_xlfn.LET( _xlpm.cnt, IFERROR(_xlfn.XMATCH("*【*", INDEX($C:$C,ROW()+1):INDEX($C:$C,ROW()+5000), 2) - 1, 5000), IF(_xlpm.cnt < 1, 0, SUBTOTAL(9, INDEX(K:K,ROW()+1):INDEX(K:K,ROW()+_xlpm.cnt))) ) | Q5: =_xlfn.LET( _xlpm.cnt, IFERROR(_xlfn.XMATCH("*【*", INDEX($C:$C,ROW()+1):INDEX($C:$C,ROW()+5000), 2) - 1, 5000), IF(_xlpm.cnt < 1, 0, SUBTOTAL(9, INDEX($Q:$Q,ROW()+1):INDEX($Q:$Q,ROW()+_xlpm.cnt))) ) | X5: =IF(E5>0,TRIM(_xlfn.REGEXREPLACE(_xlfn.REGEXREPLACE(C5,"^\s*(?:\d+\.\d+(?:\.\d+)*|-)\s+", ""),"[。.]+$", "")), "") | Z5: =_xlfn.LET( _xlpm.cnt, IFERROR(_xlfn.XMATCH("*【*", INDEX($C:$C,ROW()+1):INDEX($C:$C,ROW()+5000), 2) - 1, 5000), IF(_xlpm.cnt < 1, 0, SUBTOTAL(9, INDEX(Z:Z,ROW()+1):INDEX(Z:Z,ROW()+_xlpm.cnt))) ) | AB5: =_xlfn.LET( _xlpm.cnt, IFERROR(_xlfn.XMATCH("*【*", INDEX($C:$C,ROW()+1):INDEX($C:$C,ROW()+5000), 2) - 1, 5000), IF(_xlpm.cnt < 1, 0, SUBTOTAL(9, INDEX(AB:AB,ROW()+1):INDEX(AB:AB,ROW()+_xlpm.cnt))) ) | AI5: =_xlfn.LET( _xlpm.cnt, IFERROR(_xlfn.XMATCH("*【*", INDEX($C:$C,ROW()+1):INDEX($C:$C,ROW()+5000), 2) - 1, 5000), IF(_xlpm.cnt < 1, 0, SUBTOTAL(9, INDEX(AI:AI,ROW()+1):INDEX(AI:AI,ROW()+_xlpm.cnt))) )
C6: 《示例子分部》 | K6: {=_xlfn.LET( _xlpm.跨度, 500, _xlpm.区, INDEX($C:$C,ROW()+1):INDEX($C:$C,ROW()+_xlpm.跨度), _xlpm.cnt, IFERROR(_xlfn.XMATCH(TRUE, _xlfn.REGEXTEST(_xlpm.区, "[《【]")) - 1, _xlpm.跨度), IF(_xlpm.cnt < 1, 0, SUBTOTAL(9, INDEX(K:K,ROW()+1):INDEX(K:K,ROW()+_xlpm.cnt))) )} | Q6: {=_xlfn.LET( _xlpm.跨度, 500, _xlpm.区, INDEX($C:$C,ROW()+1):INDEX($C:$C,ROW()+_xlpm.跨度), _xlpm.cnt, IFERROR(_xlfn.XMATCH(TRUE, _xlfn.REGEXTEST(_xlpm.区, "[《【]")) - 1, _xlpm.跨度), IF(_xlpm.cnt < 1, 0, SUBTOTAL(9, INDEX(Q:Q,ROW()+1):INDEX(Q:Q,ROW()+_xlpm.cnt))) )} | X6: =IF(E6>0,TRIM(_xlfn.REGEXREPLACE(_xlfn.REGEXREPLACE(C6,"^\s*(?:\d+\.\d+(?:\.\d+)*|-)\s+", ""),"[。.]+$", "")), "") | Z6: {=_xlfn.LET( _xlpm.跨度, 500, _xlpm.区, INDEX($C:$C,ROW()+1):INDEX($C:$C,ROW()+_xlpm.跨度), _xlpm.cnt, IFERROR(_xlfn.XMATCH(TRUE, _xlfn.REGEXTEST(_xlpm.区, "[《【]")) - 1, _xlpm.跨度), IF(_xlpm.cnt < 1, 0, SUBTOTAL(9, INDEX(Z:Z,ROW()+1):INDEX(Z:Z,ROW()+_xlpm.cnt))) )} | AB6: {=_xlfn.LET( _xlpm.跨度, 500, _xlpm.区, INDEX($C:$C,ROW()+1):INDEX($C:$C,ROW()+_xlpm.跨度), _xlpm.cnt, IFERROR(_xlfn.XMATCH(TRUE, _xlfn.REGEXTEST(_xlpm.区, "[《【]")) - 1, _xlpm.跨度), IF(_xlpm.cnt < 1, 0, SUBTOTAL(9, INDEX(AB:AB,ROW()+1):INDEX(AB:AB,ROW()+_xlpm.cnt))) )} | AI6: {=_xlfn.LET( _xlpm.跨度, 500, _xlpm.区, INDEX($C:$C,ROW()+1):INDEX($C:$C,ROW()+_xlpm.跨度), _xlpm.cnt, IFERROR(_xlfn.XMATCH(TRUE, _xlfn.REGEXTEST(_xlpm.区, "[《【]")) - 1, _xlpm.跨度), IF(_xlpm.cnt < 1, 0, SUBTOTAL(9, INDEX(AI:AI,ROW()+1):INDEX(AI:AI,ROW()+_xlpm.cnt))) )}
C7: {TESTS, REPORTS AND RECORDS} | X7: =IF(E7>0,TRIM(_xlfn.REGEXREPLACE(_xlfn.REGEXREPLACE(C7,"^\s*(?:\d+\.\d+(?:\.\d+)*|-)\s+", ""),"[。.]+$", "")), "")
A8: {=_xlfn.LET( _xlpm.Item,C8, _xlpm.Unit,D8, _xlpm.DataRng,$C$4:C8, _xlpm.Level1,IFERROR(LOOKUP(2,1/ISNUMBER(FIND("【",_xlpm.DataRng)),_xlpm.DataRng),""), _xlpm.Level2,IFERROR(LOOKUP(2,1/ISNUMBER(FIND("《",_xlpm.DataRng)),_xlpm.DataRng),""), _xlpm.Level3,IFERROR(LOOKUP(2,1/ISNUMBER(FIND("{",_xlpm.DataRng)),_xlpm.DataRng),""), _xlpm.Strip,_xlfn.LAMBDA(_xlpm.x,MID(_xlfn.REGEXREPLACE(TRIM(_xlpm.x),"[~*_|]",""),2,9)), _xlpm.Hash,_xlfn.LAMBDA(_xlpm.x,IF(LEN(_xlpm.x)=0,0,SUMPRODUCT(CODE(MID(_xlpm.x,_xlfn.SEQUENCE(LEN(_xlpm.x)),1))*_xlfn.SEQUENCE(LEN(_xlpm.x))))), _xlpm.Strip(_xlpm.Level1)&"|"&_xlpm.Strip(_xlpm.Level2)&"|"&_xlpm.Strip(_xlpm.Level3)&"|"&_xlpm.Hash(_xlpm.Item&"@"&_xlpm.Unit&E8) )} | B8: 12 | C8: 示例明细项 A | D8: No. | E8: 598 | G8: =PRODUCT(M8*G$2,$F8) | H8: =PRODUCT(N8*H$2,$F8) | I8: =PRODUCT(O8*I$2,$F8) | K8: =J8*$E8 | M8: =P8*75% | Q8: =P8*$E8 | R8: Civil & Decoration | S8: A.31 | T8: Testing and Monitoring | U8: Pile Foundation Testing | V8: Low-strain Pile Integrity Testing (PIT) | W8: {=_xlfn.LET( _xlpm.Item,S8, _xlpm.Unit,X8, _xlpm.Hash,_xlfn.LAMBDA(_xlpm.x,IF(LEN(_xlpm.x)=0,0,SUMPRODUCT(CODE(MID(_xlpm.x,_xlfn.SEQUENCE(LEN(_xlpm.x)),1))*_xlfn.SEQUENCE(LEN(_xlpm.x))))), _xlpm.Item&"|"&_xlpm.Hash(_xlpm.Unit) )} | X8: =IF(E8>0,TRIM(_xlfn.REGEXREPLACE(_xlfn.REGEXREPLACE(C8,"^\s*(?:\d+\.\d+(?:\.\d+)*|-)\s+", ""),"[。.]+$", "")), "") | Y8: {=IFERROR(VLOOKUP(W8,UniqueShot!F:AJ,COLUMN(UniqueShot!AI:AI)-COLUMN(UniqueShot!F:F)+1,FALSE),0)} | Z8: =Y8*$E8 | AA8: =IFERROR(VLOOKUP(W8,UniqueShot!F:M,5,FALSE),0) | AB8: =AA8*$E8 | AI8: =AH8*$E8
A9: {=_xlfn.LET( _xlpm.Item,C9, _xlpm.Unit,D9, _xlpm.DataRng,$C$4:C9, _xlpm.Level1,IFERROR(LOOKUP(2,1/ISNUMBER(FIND("【",_xlpm.DataRng)),_xlpm.DataRng),""), _xlpm.Level2,IFERROR(LOOKUP(2,1/ISNUMBER(FIND("《",_xlpm.DataRng)),_xlpm.DataRng),""), _xlpm.Level3,IFERROR(LOOKUP(2,1/ISNUMBER(FIND("{",_xlpm.DataRng)),_xlpm.DataRng),""), _xlpm.Strip,_xlfn.LAMBDA(_xlpm.x,MID(_xlfn.REGEXREPLACE(TRIM(_xlpm.x),"[~*_|]",""),2,9)), _xlpm.Hash,_xlfn.LAMBDA(_xlpm.x,IF(LEN(_xlpm.x)=0,0,SUMPRODUCT(CODE(MID(_xlpm.x,_xlfn.SEQUENCE(LEN(_xlpm.x)),1))*_xlfn.SEQUENCE(LEN(_xlpm.x))))), _xlpm.Strip(_xlpm.Level1)&"|"&_xlpm.Strip(_xlpm.Level2)&"|"&_xlpm.Strip(_xlpm.Level3)&"|"&_xlpm.Hash(_xlpm.Item&"@"&_xlpm.Unit&E9) )} | B9: 13 | C9: Core-drilling test | D9: No. | E9: 598 | G9: =PRODUCT(M9*G$2,$F9) | H9: =PRODUCT(N9*H$2,$F9) | I9: =PRODUCT(O9*I$2,$F9) | K9: =J9*$E9 | M9: =P9*75% | Q9: =P9*$E9 | R9: Civil & Decoration | S9: A.31 | T9: Testing and Monitoring | U9: Pile Foundation Testing | V9: Pile Core Drilling Inspection | W9: {=_xlfn.LET( _xlpm.Item,S9, _xlpm.Unit,X9, _xlpm.Hash,_xlfn.LAMBDA(_xlpm.x,IF(LEN(_xlpm.x)=0,0,SUMPRODUCT(CODE(MID(_xlpm.x,_xlfn.SEQUENCE(LEN(_xlpm.x)),1))*_xlfn.SEQUENCE(LEN(_xlpm.x))))), _xlpm.Item&"|"&_xlpm.Hash(_xlpm.Unit) )} | X9: =IF(E9>0,TRIM(_xlfn.REGEXREPLACE(_xlfn.REGEXREPLACE(C9,"^\s*(?:\d+\.\d+(?:\.\d+)*|-)\s+", ""),"[。.]+$", "")), "") | Y9: {=IFERROR(VLOOKUP(W9,UniqueShot!F:AJ,COLUMN(UniqueShot!AI:AI)-COLUMN(UniqueShot!F:F)+1,FALSE),0)} | Z9: =Y9*$E9 | AA9: =IFERROR(VLOOKUP(W9,UniqueShot!F:M,5,FALSE),0) | AB9: =AA9*$E9 | AI9: =AH9*$E9
A10: {=_xlfn.LET( _xlpm.Item,C10, _xlpm.Unit,D10, _xlpm.DataRng,$C$4:C10, _xlpm.Level1,IFERROR(LOOKUP(2,1/ISNUMBER(FIND("【",_xlpm.DataRng)),_xlpm.DataRng),""), _xlpm.Level2,IFERROR(LOOKUP(2,1/ISNUMBER(FIND("《",_xlpm.DataRng)),_xlpm.DataRng),""), _xlpm.Level3,IFERROR(LOOKUP(2,1/ISNUMBER(FIND("{",_xlpm.DataRng)),_xlpm.DataRng),""), _xlpm.Strip,_xlfn.LAMBDA(_xlpm.x,MID(_xlfn.REGEXREPLACE(TRIM(_xlpm.x),"[~*_|]",""),2,9)), _xlpm.Hash,_xlfn.LAMBDA(_xlpm.x,IF(LEN(_xlpm.x)=0,0,SUMPRODUCT(CODE(MID(_xlpm.x,_xlfn.SEQUENCE(LEN(_xlpm.x)),1))*_xlfn.SEQUENCE(LEN(_xlpm.x))))), _xlpm.Strip(_xlpm.Level1)&"|"&_xlpm.Strip(_xlpm.Level2)&"|"&_xlpm.Strip(_xlpm.Level3)&"|"&_xlpm.Hash(_xlpm.Item&"@"&_xlpm.Unit&E10) )} | B10: 14 | C10: Cross-hole sonic logging test (including installation of embedded sonic tubes in piles) | D10: No. | E10: 60 | G10: =PRODUCT(M10*G$2,$F10) | H10: =PRODUCT(N10*H$2,$F10) | I10: =PRODUCT(O10*I$2,$F10) | K10: =J10*$E10 | M10: =P10*75% | Q10: =P10*$E10 | R10: Civil & Decoration | S10: A.31 | T10: Testing and Monitoring | U10: Pile Foundation Testing | V10: Cross-hole Sonic Logging (CSL) | W10: {=_xlfn.LET( _xlpm.Item,S10, _xlpm.Unit,X10, _xlpm.Hash,_xlfn.LAMBDA(_xlpm.x,IF(LEN(_xlpm.x)=0,0,SUMPRODUCT(CODE(MID(_xlpm.x,_xlfn.SEQUENCE(LEN(_xlpm.x)),1))*_xlfn.SEQUENCE(LEN(_xlpm.x))))), _xlpm.Item&"|"&_xlpm.Hash(_xlpm.Unit) )} | X10: =IF(E10>0,TRIM(_xlfn.REGEXREPLACE(_xlfn.REGEXREPLACE(C10,"^\s*(?:\d+\.\d+(?:\.\d+)*|-)\s+", ""),"[。.]+$", "")), "") | Y10: {=IFERROR(VLOOKUP(W10,UniqueShot!F:AJ,COLUMN(UniqueShot!AI:AI)-COLUMN(UniqueShot!F:F)+1,FALSE),0)} | Z10: =Y10*$E10 | AA10: =IFERROR(VLOOKUP(W10,UniqueShot!F:M,5,FALSE),0) | AB10: =AA10*$E10 | AI10: =AH10*$E10
A11: {=_xlfn.LET( _xlpm.Item,C11, _xlpm.Unit,D11, _xlpm.DataRng,$C$4:C11, _xlpm.Level1,IFERROR(LOOKUP(2,1/ISNUMBER(FIND("【",_xlpm.DataRng)),_xlpm.DataRng),""), _xlpm.Level2,IFERROR(LOOKUP(2,1/ISNUMBER(FIND("《",_xlpm.DataRng)),_xlpm.DataRng),""), _xlpm.Level3,IFERROR(LOOKUP(2,1/ISNUMBER(FIND("{",_xlpm.DataRng)),_xlpm.DataRng),""), _xlpm.Strip,_xlfn.LAMBDA(_xlpm.x,MID(_xlfn.REGEXREPLACE(TRIM(_xlpm.x),"[~*_|]",""),2,9)), _xlpm.Hash,_xlfn.LAMBDA(_xlpm.x,IF(LEN(_xlpm.x)=0,0,SUMPRODUCT(CODE(MID(_xlpm.x,_xlfn.SEQUENCE(LEN(_xlpm.x)),1))*_xlfn.SEQUENCE(LEN(_xlpm.x))))), _xlpm.Strip(_xlpm.Level1)&"|"&_xlpm.Strip(_xlpm.Level2)&"|"&_xlpm.Strip(_xlpm.Level3)&"|"&_xlpm.Hash(_xlpm.Item&"@"&_xlpm.Unit&E11) )} | B11: 15 | C11: Single-pile vertical compressive static load test | D11: No. | E11: 6 | G11: =PRODUCT(M11*G$2,$F11) | H11: =PRODUCT(N11*H$2,$F11) | I11: =PRODUCT(O11*I$2,$F11) | K11: =J11*$E11 | M11: =P11*75% | Q11: =P11*$E11 | R11: Civil & Decoration | S11: A.31 | T11: Testing and Monitoring | U11: Pile Foundation Testing | V11: Static Load Test for Single Pile Capacity | W11: {=_xlfn.LET( _xlpm.Item,S11, _xlpm.Unit,X11, _xlpm.Hash,_xlfn.LAMBDA(_xlpm.x,IF(LEN(_xlpm.x)=0,0,SUMPRODUCT(CODE(MID(_xlpm.x,_xlfn.SEQUENCE(LEN(_xlpm.x)),1))*_xlfn.SEQUENCE(LEN(_xlpm.x))))), _xlpm.Item&"|"&_xlpm.Hash(_xlpm.Unit) )} | X11: =IF(E11>0,TRIM(_xlfn.REGEXREPLACE(_xlfn.REGEXREPLACE(C11,"^\s*(?:\d+\.\d+(?:\.\d+)*|-)\s+", ""),"[。.]+$", "")), "") | Y11: {=IFERROR(VLOOKUP(W11,UniqueShot!F:AJ,COLUMN(UniqueShot!AI:AI)-COLUMN(UniqueShot!F:F)+1,FALSE),0)} | Z11: =Y11*$E11 | AA11: =IFERROR(VLOOKUP(W11,UniqueShot!F:M,5,FALSE),0) | AB11: =AA11*$E11 | AI11: =AH11*$E11
A12: {=_xlfn.LET( _xlpm.Item,C12, _xlpm.Unit,D12, _xlpm.DataRng,$C$4:C12, _xlpm.Level1,IFERROR(LOOKUP(2,1/ISNUMBER(FIND("【",_xlpm.DataRng)),_xlpm.DataRng),""), _xlpm.Level2,IFERROR(LOOKUP(2,1/ISNUMBER(FIND("《",_xlpm.DataRng)),_xlpm.DataRng),""), _xlpm.Level3,IFERROR(LOOKUP(2,1/ISNUMBER(FIND("{",_xlpm.DataRng)),_xlpm.DataRng),""), _xlpm.Strip,_xlfn.LAMBDA(_xlpm.x,MID(_xlfn.REGEXREPLACE(TRIM(_xlpm.x),"[~*_|]",""),2,9)), _xlpm.Hash,_xlfn.LAMBDA(_xlpm.x,IF(LEN(_xlpm.x)=0,0,SUMPRODUCT(CODE(MID(_xlpm.x,_xlfn.SEQUENCE(LEN(_xlpm.x)),1))*_xlfn.SEQUENCE(LEN(_xlpm.x))))), _xlpm.Strip(_xlpm.Level1)&"|"&_xlpm.Strip(_xlpm.Level2)&"|"&_xlpm.Strip(_xlpm.Level3)&"|"&_xlpm.Hash(_xlpm.Item&"@"&_xlpm.Unit&E12) )} | B12: 16 | C12: Exploratory drilling test | D12: No. | E12: 598 | G12: =PRODUCT(M12*G$2,$F12) | H12: =PRODUCT(N12*H$2,$F12) | I12: =PRODUCT(O12*I$2,$F12) | K12: =J12*$E12 | M12: =P12*75% | Q12: =P12*$E12 | R12: Civil & Decoration | S12: A.31 | T12: Testing and Monitoring | U12: Pile Foundation Testing | V12: Pile Core Drilling Inspection | W12: {=_xlfn.LET( _xlpm.Item,S12, _xlpm.Unit,X12, _xlpm.Hash,_xlfn.LAMBDA(_xlpm.x,IF(LEN(_xlpm.x)=0,0,SUMPRODUCT(CODE(MID(_xlpm.x,_xlfn.SEQUENCE(LEN(_xlpm.x)),1))*_xlfn.SEQUENCE(LEN(_xlpm.x))))), _xlpm.Item&"|"&_xlpm.Hash(_xlpm.Unit) )} | X12: =IF(E12>0,TRIM(_xlfn.REGEXREPLACE(_xlfn.REGEXREPLACE(C12,"^\s*(?:\d+\.\d+(?:\.\d+)*|-)\s+", ""),"[。.]+$", "")), "") | Y12: {=IFERROR(VLOOKUP(W12,UniqueShot!F:AJ,COLUMN(UniqueShot!AI:AI)-COLUMN(UniqueShot!F:F)+1,FALSE),0)} | Z12: =Y12*$E12 | AA12: =IFERROR(VLOOKUP(W12,UniqueShot!F:M,5,FALSE),0) | AB12: =AA12*$E12 | AI12: =AH12*$E12
A13: {=_xlfn.LET( _xlpm.Item,C13, _xlpm.Unit,D13, _xlpm.DataRng,$C$4:C13, _xlpm.Level1,IFERROR(LOOKUP(2,1/ISNUMBER(FIND("【",_xlpm.DataRng)),_xlpm.DataRng),""), _xlpm.Level2,IFERROR(LOOKUP(2,1/ISNUMBER(FIND("《",_xlpm.DataRng)),_xlpm.DataRng),""), _xlpm.Level3,IFERROR(LOOKUP(2,1/ISNUMBER(FIND("{",_xlpm.DataRng)),_xlpm.DataRng),""), _xlpm.Strip,_xlfn.LAMBDA(_xlpm.x,MID(_xlfn.REGEXREPLACE(TRIM(_xlpm.x),"[~*_|]",""),2,9)), _xlpm.Hash,_xlfn.LAMBDA(_xlpm.x,IF(LEN(_xlpm.x)=0,0,SUMPRODUCT(CODE(MID(_xlpm.x,_xlfn.SEQUENCE(LEN(_xlpm.x)),1))*_xlfn.SEQUENCE(LEN(_xlpm.x))))), _xlpm.Strip(_xlpm.Level1)&"|"&_xlpm.Strip(_xlpm.Level2)&"|"&_xlpm.Strip(_xlpm.Level3)&"|"&_xlpm.Hash(_xlpm.Item&"@"&_xlpm.Unit&E13) )} | B13: 17 | C13: Static uplift and lateral load tests | D13: No. | E13: 6 | G13: =PRODUCT(M13*G$2,$F13) | H13: =PRODUCT(N13*H$2,$F13) | I13: =PRODUCT(O13*I$2,$F13) | K13: =J13*$E13 | M13: =P13*75% | Q13: =P13*$E13 | R13: Civil & Decoration | S13: A.31 | T13: Testing and Monitoring | U13: Pile Foundation Testing | V13: Static Load Test | W13: {=_xlfn.LET( _xlpm.Item,S13, _xlpm.Unit,X13, _xlpm.Hash,_xlfn.LAMBDA(_xlpm.x,IF(LEN(_xlpm.x)=0,0,SUMPRODUCT(CODE(MID(_xlpm.x,_xlfn.SEQUENCE(LEN(_xlpm.x)),1))*_xlfn.SEQUENCE(LEN(_xlpm.x))))), _xlpm.Item&"|"&_xlpm.Hash(_xlpm.Unit) )} | X13: =IF(E13>0,TRIM(_xlfn.REGEXREPLACE(_xlfn.REGEXREPLACE(C13,"^\s*(?:\d+\.\d+(?:\.\d+)*|-)\s+", ""),"[。.]+$", "")), "") | Y13: {=IFERROR(VLOOKUP(W13,UniqueShot!F:AJ,COLUMN(UniqueShot!AI:AI)-COLUMN(UniqueShot!F:F)+1,FALSE),0)} | Z13: =Y13*$E13 | AA13: =IFERROR(VLOOKUP(W13,UniqueShot!F:M,5,FALSE),0) | AB13: =AA13*$E13 | AI13: =AH13*$E13
A14: {=_xlfn.LET( _xlpm.Item,C14, _xlpm.Unit,D14, _xlpm.DataRng,$C$4:C14, _xlpm.Level1,IFERROR(LOOKUP(2,1/ISNUMBER(FIND("【",_xlpm.DataRng)),_xlpm.DataRng),""), _xlpm.Level2,IFERROR(LOOKUP(2,1/ISNUMBER(FIND("《",_xlpm.DataRng)),_xlpm.DataRng),""), _xlpm.Level3,IFERROR(LOOKUP(2,1/ISNUMBER(FIND("{",_xlpm.DataRng)),_xlpm.DataRng),""), _xlpm.Strip,_xlfn.LAMBDA(_xlpm.x,MID(_xlfn.REGEXREPLACE(TRIM(_xlpm.x),"[~*_|]",""),2,9)), _xlpm.Hash,_xlfn.LAMBDA(_xlpm.x,IF(LEN(_xlpm.x)=0,0,SUMPRODUCT(CODE(MID(_xlpm.x,_xlfn.SEQUENCE(LEN(_xlpm.x)),1))*_xlfn.SEQUENCE(LEN(_xlpm.x))))), _xlpm.Strip(_xlpm.Level1)&"|"&_xlpm.Strip(_xlpm.Level2)&"|"&_xlpm.Strip(_xlpm.Level3)&"|"&_xlpm.Hash(_xlpm.Item&"@"&_xlpm.Unit&E14) )} | B14: 18 | C14: Construction of slurry pit | D14: M3 | E14: 12 | G14: =PRODUCT(M14*G$2,$F14) | H14: =PRODUCT(N14*H$2,$F14) | I14: =PRODUCT(O14*I$2,$F14) | K14: =J14*$E14 | M14: =P14*75% | Q14: =P14*$E14 | R14: Civil & Decoration | S14: A.03 | T14: Piling Works | U14: Bored Cast-in-place Piles | V14: Bored Cast-in-situ Piles with Slurry Support | W14: {=_xlfn.LET( _xlpm.Item,S14, _xlpm.Unit,X14, _xlpm.Hash,_xlfn.LAMBDA(_xlpm.x,IF(LEN(_xlpm.x)=0,0,SUMPRODUCT(CODE(MID(_xlpm.x,_xlfn.SEQUENCE(LEN(_xlpm.x)),1))*_xlfn.SEQUENCE(LEN(_xlpm.x))))), _xlpm.Item&"|"&_xlpm.Hash(_xlpm.Unit) )} | X14: =IF(E14>0,TRIM(_xlfn.REGEXREPLACE(_xlfn.REGEXREPLACE(C14,"^\s*(?:\d+\.\d+(?:\.\d+)*|-)\s+", ""),"[。.]+$", "")), "") | Y14: {=IFERROR(VLOOKUP(W14,UniqueShot!F:AJ,COLUMN(UniqueShot!AI:AI)-COLUMN(UniqueShot!F:F)+1,FALSE),0)} | Z14: =Y14*$E14 | AA14: =IFERROR(VLOOKUP(W14,UniqueShot!F:M,5,FALSE),0) | AB14: =AA14*$E14 | AI14: =AH14*$E14
A15: {=_xlfn.LET( _xlpm.Item,C15, _xlpm.Unit,D15, _xlpm.DataRng,$C$4:C15, _xlpm.Level1,IFERROR(LOOKUP(2,1/ISNUMBER(FIND("【",_xlpm.DataRng)),_xlpm.DataRng),""), _xlpm.Level2,IFERROR(LOOKUP(2,1/ISNUMBER(FIND("《",_xlpm.DataRng)),_xlpm.DataRng),""), _xlpm.Level3,IFERROR(LOOKUP(2,1/ISNUMBER(FIND("{",_xlpm.DataRng)),_xlpm.DataRng),""), _xlpm.Strip,_xlfn.LAMBDA(_xlpm.x,MID(_xlfn.REGEXREPLACE(TRIM(_xlpm.x),"[~*_|]",""),2,9)), _xlpm.Hash,_xlfn.LAMBDA(_xlpm.x,IF(LEN(_xlpm.x)=0,0,SUMPRODUCT(CODE(MID(_xlpm.x,_xlfn.SEQUENCE(LEN(_xlpm.x)),1))*_xlfn.SEQUENCE(LEN(_xlpm.x))))), _xlpm.Strip(_xlpm.Level1)&"|"&_xlpm.Strip(_xlpm.Level2)&"|"&_xlpm.Strip(_xlpm.Level3)&"|"&_xlpm.Hash(_xlpm.Item&"@"&_xlpm.Unit&E15) )} | B15: 19 | C15: Provide soil test report | D15: Item | E15: 1 | G15: =PRODUCT(M15*G$2,$F15) | H15: =PRODUCT(N15*H$2,$F15) | I15: =PRODUCT(O15*I$2,$F15) | K15: =J15*$E15 | M15: =P15*75% | Q15: =P15*$E15 | R15: Civil & Decoration | S15: A.31 | T15: Testing and Monitoring | U15: Ground and Support Testing & Monitoring | V15: Ground Treatment Testing and Inspection | W15: {=_xlfn.LET( _xlpm.Item,S15, _xlpm.Unit,X15, _xlpm.Hash,_xlfn.LAMBDA(_xlpm.x,IF(LEN(_xlpm.x)=0,0,SUMPRODUCT(CODE(MID(_xlpm.x,_xlfn.SEQUENCE(LEN(_xlpm.x)),1))*_xlfn.SEQUENCE(LEN(_xlpm.x))))), _xlpm.Item&"|"&_xlpm.Hash(_xlpm.Unit) )} | X15: =IF(E15>0,TRIM(_xlfn.REGEXREPLACE(_xlfn.REGEXREPLACE(C15,"^\s*(?:\d+\.\d+(?:\.\d+)*|-)\s+", ""),"[。.]+$", "")), "") | Y15: {=IFERROR(VLOOKUP(W15,UniqueShot!F:AJ,COLUMN(UniqueShot!AI:AI)-COLUMN(UniqueShot!F:F)+1,FALSE),0)} | Z15: =Y15*$E15 | AA15: =IFERROR(VLOOKUP(W15,UniqueShot!F:M,5,FALSE),0) | AB15: =AA15*$E15 | AI15: =AH15*$E15
C16: {Other} | X16: =IF(E16>0,TRIM(_xlfn.REGEXREPLACE(_xlfn.REGEXREPLACE(C16,"^\s*(?:\d+\.\d+(?:\.\d+)*|-)\s+", ""),"[。.]+$", "")), "")
A17: {=_xlfn.LET( _xlpm.Item,C17, _xlpm.Unit,D17, _xlpm.DataRng,$C$4:C17, _xlpm.Level1,IFERROR(LOOKUP(2,1/ISNUMBER(FIND("【",_xlpm.DataRng)),_xlpm.DataRng),""), _xlpm.Level2,IFERROR(LOOKUP(2,1/ISNUMBER(FIND("《",_xlpm.DataRng)),_xlpm.DataRng),""), _xlpm.Level3,IFERROR(LOOKUP(2,1/ISNUMBER(FIND("{",_xlpm.DataRng)),_xlpm.DataRng),""), _xlpm.Strip,_xlfn.LAMBDA(_xlpm.x,MID(_xlfn.REGEXREPLACE(TRIM(_xlpm.x),"[~*_|]",""),2,9)), _xlpm.Hash,_xlfn.LAMBDA(_xlpm.x,IF(LEN(_xlpm.x)=0,0,SUMPRODUCT(CODE(MID(_xlpm.x,_xlfn.SEQUENCE(LEN(_xlpm.x)),1))*_xlfn.SEQUENCE(LEN(_xlpm.x))))), _xlpm.Strip(_xlpm.Level1)&"|"&_xlpm.Strip(_xlpm.Level2)&"|"&_xlpm.Strip(_xlpm.Level3)&"|"&_xlpm.Hash(_xlpm.Item&"@"&_xlpm.Unit&E17) )} | B17: 20 | C17: Allow for all other works and costs not included above but necessary for completion of the "PILING WORKS" as shown on the Drawings and described in the Specification. | D17: Item | E17: 1 | G17: =PRODUCT(M17*G$2,$F17) | H17: =PRODUCT(N17*H$2,$F17) | I17: =PRODUCT(O17*I$2,$F17) | K17: =J17*$E17 | M17: =P17*75% | Q17: =P17*$E17 | R17: Civil & Decoration | S17: A.03 | T17: Piling Works | U17: Bored Cast-in-place Piles | W17: {=_xlfn.LET( _xlpm.Item,S17, _xlpm.Unit,X17, _xlpm.Hash,_xlfn.LAMBDA(_xlpm.x,IF(LEN(_xlpm.x)=0,0,SUMPRODUCT(CODE(MID(_xlpm.x,_xlfn.SEQUENCE(LEN(_xlpm.x)),1))*_xlfn.SEQUENCE(LEN(_xlpm.x))))), _xlpm.Item&"|"&_xlpm.Hash(_xlpm.Unit) )} | X17: =IF(E17>0,TRIM(_xlfn.REGEXREPLACE(_xlfn.REGEXREPLACE(C17,"^\s*(?:\d+\.\d+(?:\.\d+)*|-)\s+", ""),"[。.]+$", "")), "") | Y17: {=IFERROR(VLOOKUP(W17,UniqueShot!F:AJ,COLUMN(UniqueShot!AI:AI)-COLUMN(UniqueShot!F:F)+1,FALSE),0)} | Z17: =Y17*$E17 | AA17: =IFERROR(VLOOKUP(W17,UniqueShot!F:M,5,FALSE),0) | AB17: =AA17*$E17 | AI17: =AH17*$E17
C18: Allow for all other works and costs not included above but necessary for completion of the "PILING WORKS" as shown on the Drawings and described in the Specification. | X18: =IF(E18>0,TRIM(_xlfn.REGEXREPLACE(_xlfn.REGEXREPLACE(C18,"^\s*(?:\d+\.\d+(?:\.\d+)*|-)\s+", ""),"[。.]+$", "")), "")
C19: 《2.2 - Excavation and Backfilling》 | K19: {=_xlfn.LET( _xlpm.跨度, 500, _xlpm.区, INDEX($C:$C,ROW()+1):INDEX($C:$C,ROW()+_xlpm.跨度), _xlpm.cnt, IFERROR(_xlfn.XMATCH(TRUE, _xlfn.REGEXTEST(_xlpm.区, "[《【]")) - 1, _xlpm.跨度), IF(_xlpm.cnt < 1, 0, SUBTOTAL(9, INDEX(K:K,ROW()+1):INDEX(K:K,ROW()+_xlpm.cnt))) )} | Q19: {=_xlfn.LET( _xlpm.跨度, 500, _xlpm.区, INDEX($C:$C,ROW()+1):INDEX($C:$C,ROW()+_xlpm.跨度), _xlpm.cnt, IFERROR(_xlfn.XMATCH(TRUE, _xlfn.REGEXTEST(_xlpm.区, "[《【]")) - 1, _xlpm.跨度), IF(_xlpm.cnt < 1, 0, SUBTOTAL(9, INDEX(Q:Q,ROW()+1):INDEX(Q:Q,ROW()+_xlpm.cnt))) )} | X19: =IF(E19>0,TRIM(_xlfn.REGEXREPLACE(_xlfn.REGEXREPLACE(C19,"^\s*(?:\d+\.\d+(?:\.\d+)*|-)\s+", ""),"[。.]+$", "")), "") | Z19: {=_xlfn.LET( _xlpm.跨度, 500, _xlpm.区, INDEX($C:$C,ROW()+1):INDEX($C:$C,ROW()+_xlpm.跨度), _xlpm.cnt, IFERROR(_xlfn.XMATCH(TRUE, _xlfn.REGEXTEST(_xlpm.区, "[《【]")) - 1, _xlpm.跨度), IF(_xlpm.cnt < 1, 0, SUBTOTAL(9, INDEX(Z:Z,ROW()+1):INDEX(Z:Z,ROW()+_xlpm.cnt))) )} | AB19: {=_xlfn.LET( _xlpm.跨度, 500, _xlpm.区, INDEX($C:$C,ROW()+1):INDEX($C:$C,ROW()+_xlpm.跨度), _xlpm.cnt, IFERROR(_xlfn.XMATCH(TRUE, _xlfn.REGEXTEST(_xlpm.区, "[《【]")) - 1, _xlpm.跨度), IF(_xlpm.cnt < 1, 0, SUBTOTAL(9, INDEX(AB:AB,ROW()+1):INDEX(AB:AB,ROW()+_xlpm.cnt))) )} | AI19: {=_xlfn.LET( _xlpm.跨度, 500, _xlpm.区, INDEX($C:$C,ROW()+1):INDEX($C:$C,ROW()+_xlpm.跨度), _xlpm.cnt, IFERROR(_xlfn.XMATCH(TRUE, _xlfn.REGEXTEST(_xlpm.区, "[《【]")) - 1, _xlpm.跨度), IF(_xlpm.cnt < 1, 0, SUBTOTAL(9, INDEX(AI:AI,ROW()+1):INDEX(AI:AI,ROW()+_xlpm.cnt))) )}
C20: Special Preambles | X20: =IF(E20>0,TRIM(_xlfn.REGEXREPLACE(_xlfn.REGEXREPLACE(C20,"^\s*(?:\d+\.\d+(?:\.\d+)*|-)\s+", ""),"[。.]+$", "")), "")
C21: In addition to the Preamble Notes, the following provisions shall apply specifically to this Contract: | X21: =IF(E21>0,TRIM(_xlfn.REGEXREPLACE(_xlfn.REGEXREPLACE(C21,"^\s*(?:\d+\.\d+(?:\.\d+)*|-)\s+", ""),"[。.]+$", "")), "")
C22: 1. The Tenderer shall include all design costs in the rates and prices. | X22: =IF(E22>0,TRIM(_xlfn.REGEXREPLACE(_xlfn.REGEXREPLACE(C22,"^\s*(?:\d+\.\d+(?:\.\d+)*|-)\s+", ""),"[。.]+$", "")), "")
C23: 2. In accordance with Clause 7.04 of the Preliminaries, the Tenderer shall complete the Schedule of Quantities and Rates. | X23: =IF(E23>0,TRIM(_xlfn.REGEXREPLACE(_xlfn.REGEXREPLACE(C23,"^\s*(?:\d+\.\d+(?:\.\d+)*|-)\s+", ""),"[。.]+$", "")), "")
C24: 3. Quantities in the Schedule of Quantities and Rates do not form part of the Contract and are at the sole risk of the Tenderer. | X24: =IF(E24>0,TRIM(_xlfn.REGEXREPLACE(_xlfn.REGEXREPLACE(C24,"^\s*(?:\d+\.\d+(?:\.\d+)*|-)\s+", ""),"[。.]+$", "")), "")
C25: 4. The quantities for all items shall be inserted by the Tenderer. | X25: =IF(E25>0,TRIM(_xlfn.REGEXREPLACE(_xlfn.REGEXREPLACE(C25,"^\s*(?:\d+\.\d+(?:\.\d+)*|-)\s+", ""),"[。.]+$", "")), "")
C26: 4. The quantities for all items shall be inserted by the Tenderer. | X26: =IF(E26>0,TRIM(_xlfn.REGEXREPLACE(_xlfn.REGEXREPLACE(C26,"^\s*(?:\d+\.\d+(?:\.\d+)*|-)\s+", ""),"[。.]+$", "")), "")
C27: 《2.2 - Excavation and Backfilling》 | K27: {=_xlfn.LET( _xlpm.跨度, 500, _xlpm.区, INDEX($C:$C,ROW()+1):INDEX($C:$C,ROW()+_xlpm.跨度), _xlpm.cnt, IFERROR(_xlfn.XMATCH(TRUE, _xlfn.REGEXTEST(_xlpm.区, "[《【]")) - 1, _xlpm.跨度), IF(_xlpm.cnt < 1, 0, SUBTOTAL(9, INDEX(K:K,ROW()+1):INDEX(K:K,ROW()+_xlpm.cnt))) )} | Q27: {=_xlfn.LET( _xlpm.跨度, 500, _xlpm.区, INDEX($C:$C,ROW()+1):INDEX($C:$C,ROW()+_xlpm.跨度), _xlpm.cnt, IFERROR(_xlfn.XMATCH(TRUE, _xlfn.REGEXTEST(_xlpm.区, "[《【]")) - 1, _xlpm.跨度), IF(_xlpm.cnt < 1, 0, SUBTOTAL(9, INDEX(Q:Q,ROW()+1):INDEX(Q:Q,ROW()+_xlpm.cnt))) )} | X27: =IF(E27>0,TRIM(_xlfn.REGEXREPLACE(_xlfn.REGEXREPLACE(C27,"^\s*(?:\d+\.\d+(?:\.\d+)*|-)\s+", ""),"[。.]+$", "")), "") | Z27: {=_xlfn.LET( _xlpm.跨度, 500, _xlpm.区, INDEX($C:$C,ROW()+1):INDEX($C:$C,ROW()+_xlpm.跨度), _xlpm.cnt, IFERROR(_xlfn.XMATCH(TRUE, _xlfn.REGEXTEST(_xlpm.区, "[《【]")) - 1, _xlpm.跨度), IF(_xlpm.cnt < 1, 0, SUBTOTAL(9, INDEX(Z:Z,ROW()+1):INDEX(Z:Z,ROW()+_xlpm.cnt))) )} | AB27: {=_xlfn.LET( _xlpm.跨度, 500, _xlpm.区, INDEX($C:$C,ROW()+1):INDEX($C:$C,ROW()+_xlpm.跨度), _xlpm.cnt, IFERROR(_xlfn.XMATCH(TRUE, _xlfn.REGEXTEST(_xlpm.区, "[《【]")) - 1, _xlpm.跨度), IF(_xlpm.cnt < 1, 0, SUBTOTAL(9, INDEX(AB:AB,ROW()+1):INDEX(AB:AB,ROW()+_xlpm.cnt))) )} | AI27: {=_xlfn.LET( _xlpm.跨度, 500, _xlpm.区, INDEX($C:$C,ROW()+1):INDEX($C:$C,ROW()+_xlpm.跨度), _xlpm.cnt, IFERROR(_xlfn.XMATCH(TRUE, _xlfn.REGEXTEST(_xlpm.区, "[《【]")) - 1, _xlpm.跨度), IF(_xlpm.cnt < 1, 0, SUBTOTAL(9, INDEX(AI:AI,ROW()+1):INDEX(AI:AI,ROW()+_xlpm.cnt))) )}
C28: 5. The Tenderer shall insert and price under "OTHER" on the last page of each Schedule all additional items it considers necessary for completion of the Contract. | X28: =IF(E28>0,TRIM(_xlfn.REGEXREPLACE(_xlfn.REGEXREPLACE(C28,"^\s*(?:\d+\.\d+(?:\.\d+)*|-)\s+", ""),"[。.]+$", "")), "")
C29: 6. The Tenderer shall complete the "Supply Rate", "Install Rate" and "All-in Rate" columns. The "All-in Rate" equals the "Supply Rate" plus the "Install Rate". The "Supply Rate" includes the material supply price before dispatch from the country or region of origin. The "Install Rate" includes installation, wastage and mark-up. | X29: =IF(E29>0,TRIM(_xlfn.REGEXREPLACE(_xlfn.REGEXREPLACE(C29,"^\s*(?:\d+\.\d+(?:\.\d+)*|-)\s+", ""),"[。.]+$", "")), "")
C30: {EXCAVATION} | X30: =IF(E30>0,TRIM(_xlfn.REGEXREPLACE(_xlfn.REGEXREPLACE(C30,"^\s*(?:\d+\.\d+(?:\.\d+)*|-)\s+", ""),"[。.]+$", "")), "")
A31: {=_xlfn.LET( _xlpm.Item,C31, _xlpm.Unit,D31, _xlpm.DataRng,$C$4:C31, _xlpm.Level1,IFERROR(LOOKUP(2,1/ISNUMBER(FIND("【",_xlpm.DataRng)),_xlpm.DataRng),""), _xlpm.Level2,IFERROR(LOOKUP(2,1/ISNUMBER(FIND("《",_xlpm.DataRng)),_xlpm.DataRng),""), _xlpm.Level3,IFERROR(LOOKUP(2,1/ISNUMBER(FIND("{",_xlpm.DataRng)),_xlpm.DataRng),""), _xlpm.Strip,_xlfn.LAMBDA(_xlpm.x,MID(_xlfn.REGEXREPLACE(TRIM(_xlpm.x),"[~*_|]",""),2,9)), _xlpm.Hash,_xlfn.LAMBDA(_xlpm.x,IF(LEN(_xlpm.x)=0,0,SUMPRODUCT(CODE(MID(_xlpm.x,_xlfn.SEQUENCE(LEN(_xlpm.x)),1))*_xlfn.SEQUENCE(LEN(_xlpm.x))))), _xlpm.Strip(_xlpm.Level1)&"|"&_xlpm.Strip(_xlpm.Level2)&"|"&_xlpm.Strip(_xlpm.Level3)&"|"&_xlpm.Hash(_xlpm.Item&"@"&_xlpm.Unit&E31) )} | B31: 21 | C31: 示例明细项 B | D31: m2 | E31: 11526.34 | G31: =PRODUCT(M31*G$2,$F31) | H31: =PRODUCT(N31*H$2,$F31) | I31: =PRODUCT(O31*I$2,$F31) | K31: =J31*$E31 | M31: =P31*75% | Q31: =P31*$E31 | R31: Civil & Decoration | S31: A.01 | T31: Site Preparation and Earthworks | U31: Site Levelling and Others | V31: Site Levelling | W31: {=_xlfn.LET( _xlpm.Item,S31, _xlpm.Unit,X31, _xlpm.Hash,_xlfn.LAMBDA(_xlpm.x,IF(LEN(_xlpm.x)=0,0,SUMPRODUCT(CODE(MID(_xlpm.x,_xlfn.SEQUENCE(LEN(_xlpm.x)),1))*_xlfn.SEQUENCE(LEN(_xlpm.x))))), _xlpm.Item&"|"&_xlpm.Hash(_xlpm.Unit) )} | X31: =IF(E31>0,TRIM(_xlfn.REGEXREPLACE(_xlfn.REGEXREPLACE(C31,"^\s*(?:\d+\.\d+(?:\.\d+)*|-)\s+", ""),"[。.]+$", "")), "") | Y31: {=IFERROR(VLOOKUP(W31,UniqueShot!F:AJ,COLUMN(UniqueShot!AI:AI)-COLUMN(UniqueShot!F:F)+1,FALSE),0)} | Z31: =Y31*$E31 | AA31: =IFERROR(VLOOKUP(W31,UniqueShot!F:M,5,FALSE),0) | AB31: =AA31*$E31 | AI31: =AH31*$E31
A32: {=_xlfn.LET( _xlpm.Item,C32, _xlpm.Unit,D32, _xlpm.DataRng,$C$4:C32, _xlpm.Level1,IFERROR(LOOKUP(2,1/ISNUMBER(FIND("【",_xlpm.DataRng)),_xlpm.DataRng),""), _xlpm.Level2,IFERROR(LOOKUP(2,1/ISNUMBER(FIND("《",_xlpm.DataRng)),_xlpm.DataRng),""), _xlpm.Level3,IFERROR(LOOKUP(2,1/ISNUMBER(FIND("{",_xlpm.DataRng)),_xlpm.DataRng),""), _xlpm.Strip,_xlfn.LAMBDA(_xlpm.x,MID(_xlfn.REGEXREPLACE(TRIM(_xlpm.x),"[~*_|]",""),2,9)), _xlpm.Hash,_xlfn.LAMBDA(_xlpm.x,IF(LEN(_xlpm.x)=0,0,SUMPRODUCT(CODE(MID(_xlpm.x,_xlfn.SEQUENCE(LEN(_xlpm.x)),1))*_xlfn.SEQUENCE(LEN(_xlpm.x))))), _xlpm.Strip(_xlpm.Level1)&"|"&_xlpm.Strip(_xlpm.Level2)&"|"&_xlpm.Strip(_xlpm.Level3)&"|"&_xlpm.Hash(_xlpm.Item&"@"&_xlpm.Unit&E32) )} | B32: 22 | C32: Earth excavation for cast-in-place piles | D32: m3 | E32: 4929.015 | G32: =PRODUCT(M32*G$2,$F32) | H32: =PRODUCT(N32*H$2,$F32) | I32: =PRODUCT(O32*I$2,$F32) | K32: =J32*$E32 | M32: =P32*75% | Q32: =P32*$E32 | R32: Civil & Decoration | S32: A.01 | T32: Site Preparation and Earthworks | U32: Foundation Earthworks | V32: Earthwork Excavation Between Piles and Internal Strut | W32: {=_xlfn.LET( _xlpm.Item,S32, _xlpm.Unit,X32, _xlpm.Hash,_xlfn.LAMBDA(_xlpm.x,IF(LEN(_xlpm.x)=0,0,SUMPRODUCT(CODE(MID(_xlpm.x,_xlfn.SEQUENCE(LEN(_xlpm.x)),1))*_xlfn.SEQUENCE(LEN(_xlpm.x))))), _xlpm.Item&"|"&_xlpm.Hash(_xlpm.Unit) )} | X32: =IF(E32>0,TRIM(_xlfn.REGEXREPLACE(_xlfn.REGEXREPLACE(C32,"^\s*(?:\d+\.\d+(?:\.\d+)*|-)\s+", ""),"[。.]+$", "")), "") | Y32: {=IFERROR(VLOOKUP(W32,UniqueShot!F:AJ,COLUMN(UniqueShot!AI:AI)-COLUMN(UniqueShot!F:F)+1,FALSE),0)} | Z32: =Y32*$E32 | AA32: =IFERROR(VLOOKUP(W32,UniqueShot!F:M,5,FALSE),0) | AB32: =AA32*$E32 | AI32: =AH32*$E32
A33: {=_xlfn.LET( _xlpm.Item,C33, _xlpm.Unit,D33, _xlpm.DataRng,$C$4:C33, _xlpm.Level1,IFERROR(LOOKUP(2,1/ISNUMBER(FIND("【",_xlpm.DataRng)),_xlpm.DataRng),""), _xlpm.Level2,IFERROR(LOOKUP(2,1/ISNUMBER(FIND("《",_xlpm.DataRng)),_xlpm.DataRng),""), _xlpm.Level3,IFERROR(LOOKUP(2,1/ISNUMBER(FIND("{",_xlpm.DataRng)),_xlpm.DataRng),""), _xlpm.Strip,_xlfn.LAMBDA(_xlpm.x,MID(_xlfn.REGEXREPLACE(TRIM(_xlpm.x),"[~*_|]",""),2,9)), _xlpm.Hash,_xlfn.LAMBDA(_xlpm.x,IF(LEN(_xlpm.x)=0,0,SUMPRODUCT(CODE(MID(_xlpm.x,_xlfn.SEQUENCE(LEN(_xlpm.x)),1))*_xlfn.SEQUENCE(LEN(_xlpm.x))))), _xlpm.Strip(_xlpm.Level1)&"|"&_xlpm.Strip(_xlpm.Level2)&"|"&_xlpm.Strip(_xlpm.Level3)&"|"&_xlpm.Hash(_xlpm.Item&"@"&_xlpm.Unit&E33) )} | B33: 23 | C33: Excavation | D33: m3 | E33: 23324.712 | G33: =PRODUCT(M33*G$2,$F33) | H33: =PRODUCT(N33*H$2,$F33) | I33: =PRODUCT(O33*I$2,$F33) | K33: =J33*$E33 | M33: =P33*75% | Q33: =P33*$E33 | R33: Civil & Decoration | S33: A.01 | T33: Site Preparation and Earthworks | U33: Foundation Earthworks | V33: Pit Earth Excavation | W33: {=_xlfn.LET( _xlpm.Item,S33, _xlpm.Unit,X33, _xlpm.Hash,_xlfn.LAMBDA(_xlpm.x,IF(LEN(_xlpm.x)=0,0,SUMPRODUCT(CODE(MID(_xlpm.x,_xlfn.SEQUENCE(LEN(_xlpm.x)),1))*_xlfn.SEQUENCE(LEN(_xlpm.x))))), _xlpm.Item&"|"&_xlpm.Hash(_xlpm.Unit) )} | X33: =IF(E33>0,TRIM(_xlfn.REGEXREPLACE(_xlfn.REGEXREPLACE(C33,"^\s*(?:\d+\.\d+(?:\.\d+)*|-)\s+", ""),"[。.]+$", "")), "") | Y33: {=IFERROR(VLOOKUP(W33,UniqueShot!F:AJ,COLUMN(UniqueShot!AI:AI)-COLUMN(UniqueShot!F:F)+1,FALSE),0)} | Z33: =Y33*$E33 | AA33: =IFERROR(VLOOKUP(W33,UniqueShot!F:M,5,FALSE),0) | AB33: =AA33*$E33 | AI33: =AH33*$E33
C34: Excavation | X34: =IF(E34>0,TRIM(_xlfn.REGEXREPLACE(_xlfn.REGEXREPLACE(C34,"^\s*(?:\d+\.\d+(?:\.\d+)*|-)\s+", ""),"[。.]+$", "")), "")
C35: 《2.2 - Excavation and Backfilling》 | K35: {=_xlfn.LET( _xlpm.跨度, 500, _xlpm.区, INDEX($C:$C,ROW()+1):INDEX($C:$C,ROW()+_xlpm.跨度), _xlpm.cnt, IFERROR(_xlfn.XMATCH(TRUE, _xlfn.REGEXTEST(_xlpm.区, "[《【]")) - 1, _xlpm.跨度), IF(_xlpm.cnt < 1, 0, SUBTOTAL(9, INDEX(K:K,ROW()+1):INDEX(K:K,ROW()+_xlpm.cnt))) )} | Q35: {=_xlfn.LET( _xlpm.跨度, 500, _xlpm.区, INDEX($C:$C,ROW()+1):INDEX($C:$C,ROW()+_xlpm.跨度), _xlpm.cnt, IFERROR(_xlfn.XMATCH(TRUE, _xlfn.REGEXTEST(_xlpm.区, "[《【]")) - 1, _xlpm.跨度), IF(_xlpm.cnt < 1, 0, SUBTOTAL(9, INDEX(Q:Q,ROW()+1):INDEX(Q:Q,ROW()+_xlpm.cnt))) )} | X35: =IF(E35>0,TRIM(_xlfn.REGEXREPLACE(_xlfn.REGEXREPLACE(C35,"^\s*(?:\d+\.\d+(?:\.\d+)*|-)\s+", ""),"[。.]+$", "")), "") | Z35: {=_xlfn.LET( _xlpm.跨度, 500, _xlpm.区, INDEX($C:$C,ROW()+1):INDEX($C:$C,ROW()+_xlpm.跨度), _xlpm.cnt, IFERROR(_xlfn.XMATCH(TRUE, _xlfn.REGEXTEST(_xlpm.区, "[《【]")) - 1, _xlpm.跨度), IF(_xlpm.cnt < 1, 0, SUBTOTAL(9, INDEX(Z:Z,ROW()+1):INDEX(Z:Z,ROW()+_xlpm.cnt))) )} | AB35: {=_xlfn.LET( _xlpm.跨度, 500, _xlpm.区, INDEX($C:$C,ROW()+1):INDEX($C:$C,ROW()+_xlpm.跨度), _xlpm.cnt, IFERROR(_xlfn.XMATCH(TRUE, _xlfn.REGEXTEST(_xlpm.区, "[《【]")) - 1, _xlpm.跨度), IF(_xlpm.cnt < 1, 0, SUBTOTAL(9, INDEX(AB:AB,ROW()+1):INDEX(AB:AB,ROW()+_xlpm.cnt))) )} | AI35: {=_xlfn.LET( _xlpm.跨度, 500, _xlpm.区, INDEX($C:$C,ROW()+1):INDEX($C:$C,ROW()+_xlpm.跨度), _xlpm.cnt, IFERROR(_xlfn.XMATCH(TRUE, _xlfn.REGEXTEST(_xlpm.区, "[《【]")) - 1, _xlpm.跨度), IF(_xlpm.cnt < 1, 0, SUBTOTAL(9, INDEX(AI:AI,ROW()+1):INDEX(AI:AI,ROW()+_xlpm.cnt))) )}
C36: {BACKFILLING AND DISPOSAL} | X36: =IF(E36>0,TRIM(_xlfn.REGEXREPLACE(_xlfn.REGEXREPLACE(C36,"^\s*(?:\d+\.\d+(?:\.\d+)*|-)\s+", ""),"[。.]+$", "")), "")
A37: {=_xlfn.LET( _xlpm.Item,C37, _xlpm.Unit,D37, _xlpm.DataRng,$C$4:C37, _xlpm.Level1,IFERROR(LOOKUP(2,1/ISNUMBER(FIND("【",_xlpm.DataRng)),_xlpm.DataRng),""), _xlpm.Level2,IFERROR(LOOKUP(2,1/ISNUMBER(FIND("《",_xlpm.DataRng)),_xlpm.DataRng),""), _xlpm.Level3,IFERROR(LOOKUP(2,1/ISNUMBER(FIND("{",_xlpm.DataRng)),_xlpm.DataRng),""), _xlpm.Strip,_xlfn.LAMBDA(_xlpm.x,MID(_xlfn.REGEXREPLACE(TRIM(_xlpm.x),"[~*_|]",""),2,9)), _xlpm.Hash,_xlfn.LAMBDA(_xlpm.x,IF(LEN(_xlpm.x)=0,0,SUMPRODUCT(CODE(MID(_xlpm.x,_xlfn.SEQUENCE(LEN(_xlpm.x)),1))*_xlfn.SEQUENCE(LEN(_xlpm.x))))), _xlpm.Strip(_xlpm.Level1)&"|"&_xlpm.Strip(_xlpm.Level2)&"|"&_xlpm.Strip(_xlpm.Level3)&"|"&_xlpm.Hash(_xlpm.Item&"@"&_xlpm.Unit&E37) )} | B37: 24 | C37: Earth backfilling. | D37: M3 | E37: 4929.0591 | G37: =PRODUCT(M37*G$2,$F37) | H37: =PRODUCT(N37*H$2,$F37) | I37: =PRODUCT(O37*I$2,$F37) | K37: =J37*$E37 | M37: =P37*75% | Q37: =P37*$E37 | R37: Civil & Decoration | S37: A.01 | T37: Site Preparation and Earthworks | U37: Foundation Earthworks | V37: Backfilling | W37: {=_xlfn.LET( _xlpm.Item,S37, _xlpm.Unit,X37, _xlpm.Hash,_xlfn.LAMBDA(_xlpm.x,IF(LEN(_xlpm.x)=0,0,SUMPRODUCT(CODE(MID(_xlpm.x,_xlfn.SEQUENCE(LEN(_xlpm.x)),1))*_xlfn.SEQUENCE(LEN(_xlpm.x))))), _xlpm.Item&"|"&_xlpm.Hash(_xlpm.Unit) )} | X37: =IF(E37>0,TRIM(_xlfn.REGEXREPLACE(_xlfn.REGEXREPLACE(C37,"^\s*(?:\d+\.\d+(?:\.\d+)*|-)\s+", ""),"[。.]+$", "")), "") | Y37: {=IFERROR(VLOOKUP(W37,UniqueShot!F:AJ,COLUMN(UniqueShot!AI:AI)-COLUMN(UniqueShot!F:F)+1,FALSE),0)} | Z37: =Y37*$E37 | AA37: =IFERROR(VLOOKUP(W37,UniqueShot!F:M,5,FALSE),0) | AB37: =AA37*$E37 | AI37: =AH37*$E37
A38: {=_xlfn.LET( _xlpm.Item,C38, _xlpm.Unit,D38, _xlpm.DataRng,$C$4:C38, _xlpm.Level1,IFERROR(LOOKUP(2,1/ISNUMBER(FIND("【",_xlpm.DataRng)),_xlpm.DataRng),""), _xlpm.Level2,IFERROR(LOOKUP(2,1/ISNUMBER(FIND("《",_xlpm.DataRng)),_xlpm.DataRng),""), _xlpm.Level3,IFERROR(LOOKUP(2,1/ISNUMBER(FIND("{",_xlpm.DataRng)),_xlpm.DataRng),""), _xlpm.Strip,_xlfn.LAMBDA(_xlpm.x,MID(_xlfn.REGEXREPLACE(TRIM(_xlpm.x),"[~*_|]",""),2,9)), _xlpm.Hash,_xlfn.LAMBDA(_xlpm.x,IF(LEN(_xlpm.x)=0,0,SUMPRODUCT(CODE(MID(_xlpm.x,_xlfn.SEQUENCE(LEN(_xlpm.x)),1))*_xlfn.SEQUENCE(LEN(_xlpm.x))))), _xlpm.Strip(_xlpm.Level1)&"|"&_xlpm.Strip(_xlpm.Level2)&"|"&_xlpm.Strip(_xlpm.Level3)&"|"&_xlpm.Hash(_xlpm.Item&"@"&_xlpm.Unit&E38) )} | B38: 25 | C38: Disposal of excavated soil off Site | D38: M3 | E38: 18395.653 | G38: =PRODUCT(M38*G$2,$F38) | H38: =PRODUCT(N38*H$2,$F38) | I38: =PRODUCT(O38*I$2,$F38) | K38: =J38*$E38 | M38: =P38*75% | Q38: =P38*$E38 | R38: Civil & Decoration | S38: A.01 | T38: Site Preparation and Earthworks | U38: Foundation Earthworks | W38: {=_xlfn.LET( _xlpm.Item,S38, _xlpm.Unit,X38, _xlpm.Hash,_xlfn.LAMBDA(_xlpm.x,IF(LEN(_xlpm.x)=0,0,SUMPRODUCT(CODE(MID(_xlpm.x,_xlfn.SEQUENCE(LEN(_xlpm.x)),1))*_xlfn.SEQUENCE(LEN(_xlpm.x))))), _xlpm.Item&"|"&_xlpm.Hash(_xlpm.Unit) )} | X38: =IF(E38>0,TRIM(_xlfn.REGEXREPLACE(_xlfn.REGEXREPLACE(C38,"^\s*(?:\d+\.\d+(?:\.\d+)*|-)\s+", ""),"[。.]+$", "")), "") | Y38: {=IFERROR(VLOOKUP(W38,UniqueShot!F:AJ,COLUMN(UniqueShot!AI:AI)-COLUMN(UniqueShot!F:F)+1,FALSE),0)} | Z38: =Y38*$E38 | AA38: =IFERROR(VLOOKUP(W38,UniqueShot!F:M,5,FALSE),0) | AB38: =AA38*$E38 | AI38: =AH38*$E38
C39: {TEMPORARY DRAINAGE SYSTEM} | X39: =IF(E39>0,TRIM(_xlfn.REGEXREPLACE(_xlfn.REGEXREPLACE(C39,"^\s*(?:\d+\.\d+(?:\.\d+)*|-)\s+", ""),"[。.]+$", "")), "")
A40: {=_xlfn.LET( _xlpm.Item,C40, _xlpm.Unit,D40, _xlpm.DataRng,$C$4:C40, _xlpm.Level1,IFERROR(LOOKUP(2,1/ISNUMBER(FIND("【",_xlpm.DataRng)),_xlpm.DataRng),""), _xlpm.Level2,IFERROR(LOOKUP(2,1/ISNUMBER(FIND("《",_xlpm.DataRng)),_xlpm.DataRng),""), _xlpm.Level3,IFERROR(LOOKUP(2,1/ISNUMBER(FIND("{",_xlpm.DataRng)),_xlpm.DataRng),""), _xlpm.Strip,_xlfn.LAMBDA(_xlpm.x,MID(_xlfn.REGEXREPLACE(TRIM(_xlpm.x),"[~*_|]",""),2,9)), _xlpm.Hash,_xlfn.LAMBDA(_xlpm.x,IF(LEN(_xlpm.x)=0,0,SUMPRODUCT(CODE(MID(_xlpm.x,_xlfn.SEQUENCE(LEN(_xlpm.x)),1))*_xlfn.SEQUENCE(LEN(_xlpm.x))))), _xlpm.Strip(_xlpm.Level1)&"|"&_xlpm.Strip(_xlpm.Level2)&"|"&_xlpm.Strip(_xlpm.Level3)&"|"&_xlpm.Hash(_xlpm.Item&"@"&_xlpm.Unit&E40) )} | B40: 26 | C40: Allow for the temporary drainage system. | D40: Item | E40: 1 | G40: =PRODUCT(M40*G$2,$F40) | H40: =PRODUCT(N40*H$2,$F40) | I40: =PRODUCT(O40*I$2,$F40) | K40: =J40*$E40 | M40: =P40*75% | Q40: =P40*$E40 | R40: Civil & Decoration | S40: A.01 | T40: Site Preparation and Earthworks | U40: Standalone Earthworks | W40: {=_xlfn.LET( _xlpm.Item,S40, _xlpm.Unit,X40, _xlpm.Hash,_xlfn.LAMBDA(_xlpm.x,IF(LEN(_xlpm.x)=0,0,SUMPRODUCT(CODE(MID(_xlpm.x,_xlfn.SEQUENCE(LEN(_xlpm.x)),1))*_xlfn.SEQUENCE(LEN(_xlpm.x))))), _xlpm.Item&"|"&_xlpm.Hash(_xlpm.Unit) )} | X40: =IF(E40>0,TRIM(_xlfn.REGEXREPLACE(_xlfn.REGEXREPLACE(C40,"^\s*(?:\d+\.\d+(?:\.\d+)*|-)\s+", ""),"[。.]+$", "")), "") | Y40: {=IFERROR(VLOOKUP(W40,UniqueShot!F:AJ,COLUMN(UniqueShot!AI:AI)-COLUMN(UniqueShot!F:F)+1,FALSE),0)} | Z40: =Y40*$E40 | AA40: =IFERROR(VLOOKUP(W40,UniqueShot!F:M,5,FALSE),0) | AB40: =AA40*$E40 | AI40: =AH40*$E40
...

Sheet CostSummary
A1: Summary
B38: PRELIM | C38: Preliminaries | I38: =CombineBQ!#REF! -> #REF!
B41: 100 | C41: 辅助用工 | D41: =E41 -> 14083500 | E41: 14083500
C42: 洒水车 | D42: =E42 -> 3511200 | E42: 3511200
C43: 加油车 | D43: =E43 -> 508750 | E43: 508750
C44: 发电机 | D44: =E44 -> 3357024 | E44: 3357024
C45: 其他设备 | D45: =E45 -> 2145180 | E45: 2145180
D46: =E46 -> 0
B47: 200 | C47: 工程施工其他直接费 | D47: =E47 -> 0
B48: 210 | C48: 承包商临时设施费 | D48: =E48 -> 10580858 | E48: 10580858
B49: 220 | C49: 提供给业主/监理的服务 | D49: =E49 -> 0 | E49: 0
B50: 230 | C50: 调遣费 | D50: =E50 -> 5650000 | E50: 5650000
B51: 240 | C51: 实验检测费 | D51: =E51 -> 8964258.9 | E51: 8964258.9
B52: 250 | C52: HSE专项经费 | D52: =E52 -> 26074500 | E52: 26074500
B53: 260 | C53: 现场管理费 | D53: =E53 -> 16738000 | E53: 16738000
B54: 270 | C54: 其他 | D54: =E54 -> 13000000 | E54: 13000000
D55: =E55 -> 0
B56: 300 | C56: 工程实施其他直接费 | D56: =E56 -> 0
B57: 310 | C57: 地勘及设计、设计审查费 | E57: 2800000
B58: 320 | C58: 保函及保险费 | E58: 330000
B59: 330 | C59: 施工许可证费用 | D59: =E59 -> 3550000 | E59: 3550000
B60: 340 | C60: 财务费用 | D60: =E60 -> 14205535 | E60: 14205535
B61: 350 | C61: 维修期费用 | D61: =E61 -> 0 | E61: 0
B62: 360 | C62: 其他 | D62: =E62 -> 5305600 | E62: 5305600
D63: =E63 -> 0
D64: =E64 -> 0
B65: 400 | C65: 间接费 | D65: =E65 -> 0
B66: 410 | C66: 现场管理人员费用 | D66: =E66 -> 67574473 | E66: 67574473
B67: 420 | C67: 税费（关税）
B68: 430 | C68: 预扣税 | F68: 0
B69: 440 | C69: 印花税 | F69: 0
B70: 450 | C70: 咨询费 | F70: 0
B71: 460 | C71: 风险费 | F71: 0
B72: 470 | C72: 利润 | F72: 0
A76: 开办费总计 | D76: =SUM(D36:D72) -> 1.9524888e+08 | E76: =SUM(E36:E72) -> 1.9837888e+08 | F76: =SUM(F48:F72) -> 0 | G76: 0
A79: 暂列金和配合费
A82: 工程总造价（不含增值税） | E82: =SUM(E76,GETPIVOTDATA("求和项:二航三 Amount",$A$3)) -> #REF! | F82: =SUM(F76,G39) -> 0 | G82: =SUM(G76,H39) -> 0 | H82: =SUM(H76,I39) -> 0

Sheet MainQty
A1: Main Quantity Summary
A3: Discipline | B3: SortKey | C3: Category | D3: Subcategory | E3: Unit | F3: 求和项:Qty | H3: 编号 | I3: 名称 | K3: 单位 | L3: 工程量
H7: B | I7: 《钢筋》 | K7: kg
I8: 钢筋10及以内 | K8: kg
I9: 钢筋10以外 | K9: kg
I10: 钢筋网片 | K10: m2
H12: C | I12: 《混凝土》 | K12: m3
I13: 基础混凝土 | K13: m3
I14: 梁混凝土 | K14: m3
I15: 板混凝土 | K15: m3
I16: 柱混凝土 | K16: m3
I17: 墙混凝土 | K17: m3
I18: 其他混凝土 | K18: m3
H19: D | I19: 《模板》 | K19: m2
H21: E | I21: 《装配式结构》
I22: 装配式混凝土 | K22: m3
I23: 钢结构 | K23: t
H25: F | I25: 《二次结构》
I26: 砖砌体 | K26: m3
I27: 钢砼二次结构 | K27: m3
I28: 轻质隔墙 | K28: m2
H31: G | I31: 《防水保温防腐》
I32: 室内防水 | K32: m2
I33: 地下室外防水 | K33: m2
I34: 屋面防水 | K34: m2
I35: 外墙保温 | K35: m2
I36: 屋面保温 | K36: m2
H39: G | I39: 《门窗栏杆屋顶》 | K39: 0
I40: 室内成套门 | K40: m2
I41: 室外门窗 | K41: m2
I42: 栏杆 | K42: m
I43: 玻璃雨棚幕墙 | K43: m2
I44: 金属屋顶 | K44: m2
H46: H | I46: 《楼地面》 | K46: m2
I47: 地面砂浆 | K47: m2
I48: 地面涂料 | K48: m2
I49: 地面块料 | K49: m2
H50: I | I50: 《内墙面》 | K50: m2
I51: 内墙抹灰 | K51: m2
I52: 内墙涂料 | K52: m2
...

Sheet UniqueBQ
A1: UniqueBQ 数据透视表 | N1: AI RATE | AE1: AI NORM
N2: {=VLOOKUP($H3,UniqueShot!$F:$AA,COLUMN(UniqueShot!K:K)-COLUMN(UniqueShot!$F:$F)+1,FALSE)} -> #N/A | O2: {=VLOOKUP($H3,UniqueShot!$F:$AA,COLUMN(UniqueShot!L:L)-COLUMN(UniqueShot!$F:$F)+1,FALSE)} -> #N/A | P2: {=VLOOKUP($H3,UniqueShot!$F:$AA,COLUMN(UniqueShot!M:M)-COLUMN(UniqueShot!$F:$F)+1,FALSE)} -> #N/A | Q2: {=VLOOKUP($H3,UniqueShot!$F:$AA,COLUMN(UniqueShot!N:N)-COLUMN(UniqueShot!$F:$F)+1,FALSE)} -> #N/A | R2: {=VLOOKUP($H3,UniqueShot!$F:$AA,COLUMN(UniqueShot!O:O)-COLUMN(UniqueShot!$F:$F)+1,FALSE)} -> #N/A | S2: {=VLOOKUP($H3,UniqueShot!$F:$AA,COLUMN(UniqueShot!P:P)-COLUMN(UniqueShot!$F:$F)+1,FALSE)} -> #N/A | T2: {=VLOOKUP($H3,UniqueShot!$F:$AA,COLUMN(UniqueShot!Q:Q)-COLUMN(UniqueShot!$F:$F)+1,FALSE)} -> #N/A | U2: {=VLOOKUP($H3,UniqueShot!$F:$AA,COLUMN(UniqueShot!R:R)-COLUMN(UniqueShot!$F:$F)+1,FALSE)} -> #N/A | V2: {=VLOOKUP($H3,UniqueShot!$F:$AA,COLUMN(UniqueShot!S:S)-COLUMN(UniqueShot!$F:$F)+1,FALSE)} -> #N/A | W2: {=VLOOKUP($H3,UniqueShot!$F:$AA,COLUMN(UniqueShot!U:U)-COLUMN(UniqueShot!$F:$F)+1,FALSE)} -> #N/A | X2: {=VLOOKUP($H3,UniqueShot!$F:$AA,COLUMN(UniqueShot!T:T)-COLUMN(UniqueShot!$F:$F)+1,FALSE)} -> #N/A | Y2: {=VLOOKUP($H3,UniqueShot!$F:$AA,COLUMN(UniqueShot!V:V)-COLUMN(UniqueShot!$F:$F)+1,FALSE)} -> #N/A | Z2: {=VLOOKUP($H3,UniqueShot!$F:$AA,COLUMN(UniqueShot!W:W)-COLUMN(UniqueShot!$F:$F)+1,FALSE)} -> #N/A | AA2: {=VLOOKUP($H3,UniqueShot!$F:$AA,COLUMN(UniqueShot!X:X)-COLUMN(UniqueShot!$F:$F)+1,FALSE)} -> #N/A | AB2: {=VLOOKUP($H3,UniqueShot!$F:$AA,COLUMN(UniqueShot!Y:Y)-COLUMN(UniqueShot!$F:$F)+1,FALSE)} -> #N/A | AC2: {=VLOOKUP($H3,UniqueShot!$F:$AA,COLUMN(UniqueShot!AA:AA)-COLUMN(UniqueShot!$F:$F)+1,FALSE)} -> #N/A | AE2: =IFERROR(VLOOKUP($F2,UniqueShot!$F:$AH,COLUMN(UniqueShot!AE:AE)-COLUMN(UniqueShot!$F:$F)+1,FALSE),0) -> 0 | AF2: =IFERROR(VLOOKUP($F2,UniqueShot!$F:$AH,COLUMN(UniqueShot!AF:AF)-COLUMN(UniqueShot!$F:$F)+1,FALSE),0) -> 0 | AG2: =IFERROR(VLOOKUP($F2,UniqueShot!$F:$AH,COLUMN(UniqueShot!AG:AG)-COLUMN(UniqueShot!$F:$F)+1,FALSE),0) -> 0 | AH2: =IFERROR(VLOOKUP(F2,UniqueShot!F:AJ,COLUMN(UniqueShot!AH:AH)-COLUMN(UniqueShot!F:F)+1,FALSE),0) -> 0 | AI2: =IFERROR(VLOOKUP(F2,UniqueShot!F:AJ,COLUMN(UniqueShot!AI:AI)-COLUMN(UniqueShot!F:F)+1,FALSE),0) -> 0 | AJ2: =IFERROR(VLOOKUP(F2,UniqueShot!F:AJ,COLUMN(UniqueShot!AJ:AJ)-COLUMN(UniqueShot!F:F)+1,FALSE),0) -> 0
Q3: Manual Search | U3: AI Search | AE3: Norm-AI
N4: Name | O4: Unit | P4: Rate | Q4: Name | R4: Unit | S4: Rate | T4: Conv Formula | U4: Name | V4: Unit | W4: Unit Conv Formula | X4: Rate | Y4: Curr | Z4: Ref Project | AA4: Supplier | AB4: Date | AC4: Reason | AE4: CODE | AF4: Name | AG4: Unit | AH4: Conv | AI4: Rate | AJ4: Reason

Sheet UniqueShot
A1: UniqueBQ 数据透视表 | N1: AI RATE | AE1: AI NORM
N2: 套价 | AI2: 0
I3: 值 | Q3: Manual Search | U3: AI Search | AE3: Norm-AI
A4: Discipline | B4: SortKey | C4: Category | D4: Subcategory | E4: Element | F4: BQ KEY | G4: CleanDescription | H4: Unit | I4: 求和项:Quantity | J4: 平均值项:入价 | K4: 求和项:入价 Amount | N4: Name | O4: Unit | P4: Rate | Q4: Name | R4: Unit | S4: Rate | T4: Conv Formula | U4: Name | V4: Unit | W4: Unit Conv Formula | X4: Rate | Y4: Curr | Z4: Ref Project | AA4: Supplier | AB4: Date | AC4: Reason | AE4: CODE | AF4: Name | AG4: Unit | AH4: Conv | AI4: Rate | AJ4: Reason
